<robot xmlns:xacro="https://www.ros.org/wiki/xacro">
<xacro:macro name="arm_link" params="dir">

    <xacro:cylinder_link name="arm_pitch_${dir}"
                         length="23.2" radius="15"
                         ofsx="0" ofsy="0" ofsz="${-23.2 / 2}"
                         mass="13" collision="true"/>
    <joint name="arm_pitch_${dir}" type="revolute">
        <parent link="body_link"/>
        <child link="arm_pitch_${dir}_link"/>

        <xacro:if value="${dir == 'right'}">
            <origin xyz="0 ${-0.078 / 2} 0.06498" rpy="-1.57 0 0"/>
        </xacro:if>
        <xacro:if value="${dir == 'left'}">
            <origin xyz="0 ${0.078 / 2} 0.06498" rpy="1.57 0 0"/>
        </xacro:if>

        <axis xyz="0 0 1"/>
        <xacro:if value="${dir == 'right'}">
            <limit lower="-3.14" upper="1.57" effort="10.0" velocity="1.0"/>
        </xacro:if>
        <xacro:if value="${dir == 'left'}">
            <limit lower="-1.57" upper="3.14" effort="10.0" velocity="1.0"/>
        </xacro:if>
    </joint>


    <xacro:box_link name="arm_roll_${dir}"
                    x="30" y="10" z="82.84"
                    ofsx="0" ofsy="0" ofsz="${-82.84 / 2}"
                    mass="95" collision="false" />
    <joint name="arm_roll_${dir}" type="revolute">
        <parent link="arm_pitch_${dir}_link"/>
        <child link="arm_roll_${dir}_link"/>

        <xacro:if value="${dir == 'right'}">
            <origin xyz="0 0 -0.0232" rpy="1.57 0 0"/>
        </xacro:if>
        <xacro:if value="${dir == 'left'}">
            <origin xyz="0 0 -0.0232" rpy="-1.57 0 0"/>
        </xacro:if>

        <axis xyz="1 0 0"/>
        <xacro:if value="${dir == 'right'}">
            <limit lower="${-3.14 * 7 / 6}" upper="${3.14 / 6}" effort="10.0" velocity="1.0"/>
        </xacro:if>
        <xacro:if value="${dir == 'left'}">
            <limit lower="${-3.14 / 6}" upper="${3.14 * 7 / 6}" effort="10.0" velocity="1.0"/>
        </xacro:if>
    </joint>
    

    <xacro:box_link name="hand_${dir}"
                    x="30" y="10" z="111.72"
                    ofsx="0" ofsy="0" ofsz="${-111.72 / 2}"
                    mass="27" collision="true" />
    <joint name="hand_${dir}" type="revolute">
        <parent link="arm_roll_${dir}_link"/>
        <child link="hand_${dir}_link"/>
        <origin xyz="0 0 -0.08284" rpy="0 0 0"/>

        <axis xyz="0 1 0"/>
        <limit lower="-3.14" upper="${3.14 / 4}" effort="10.0" velocity="1.0"/>
    </joint>

</xacro:macro>
</robot>